<?xml version="1.0" ?>
<!-- =================================================================================== -->
<!-- |    This document was autogenerated by xacro from /home/noetic/host_catkin_ws/src/arctos_urdf_description/urdf/arctos.xacro | -->
<!-- |    EDITING THIS FILE BY HAND IS NOT RECOMMENDED                                 | -->
<!-- =================================================================================== -->
<robot name="arctos_urdf">
    <!-- Start of Selection -->
    <material name="paint_metallic_blue_2">
        <color rgba="0.0 0.0 1.0 1.0" />
        <!-- A solid blue color that works in Gazebo -->
        <gazebo reference="base_link">
            <material>Gazebo/Blue</material>
        </gazebo>
    </material>
    <!-- End of Selection -->
    <!-- Define the world link explicitly -->
    <link name="world" />
    <!-- fix the robot to the world -->
    <joint name="world_to_base_link" type="fixed">
        <parent link="world" />
        <child link="base_link" />
    </joint>
    <link name="base_link">
        <visual>
            <origin rpy="0 0 0" xyz="0 0 0" />
            <geometry>
                <mesh filename="package://arctos_urdf_description/meshes/base_link.stl" scale="0.001 0.001 0.001" />
            </geometry>
            <material name="paint_metallic_blue_2" />
        </visual>
        <collision>
            <origin rpy="0 0 0" xyz="0 0 0" />
            <geometry>
                <mesh filename="package://arctos_urdf_description/meshes/base_link.stl" scale="0.001 0.001 0.001" />
            </geometry>
        </collision>
        <inertial>
            <origin rpy="0 0 0" xyz="0.0009375030874740357 0.047087016508753216 0.06663230338123677" />
            <mass value="7.598577592821282" />
            <inertia ixx="0.063328" ixy="-0.000434" ixz="0.000108" iyy="0.03095" iyz="0.001366" izz="0.072371" />
        </inertial>
    </link>
    <link name="Link_1_1">
        <visual>
            <origin rpy="0 0 0" xyz="-0.0 -0.000529 -0.111" />
            <geometry>
                <mesh filename="package://arctos_urdf_description/meshes/Link_1_1.stl" scale="0.001 0.001 0.001" />
            </geometry>
            <material name="paint_metallic_blue_2" />
        </visual>
        <collision>
            <origin rpy="0 0 0" xyz="-0.0 -0.000529 -0.111" />
            <geometry>
                <mesh filename="package://arctos_urdf_description/meshes/Link_1_1.stl" scale="0.001 0.001 0.001" />
            </geometry>
        </collision>
        <inertial>
            <origin rpy="0 0 0" xyz="0.0022188890353287776 -0.004863444449475237 0.08546835509394825" />
            <mass value="10.394711633971145" />
            <inertia ixx="0.061139" ixy="0.00017" ixz="-0.00148" iyy="0.073854" iyz="0.003835" izz="0.05669" />
        </inertial>
    </link>
    <link name="Link_2_1">
        <visual>
            <origin rpy="0 0 0" xyz="0.05713 0.020356 -0.289378" />
            <geometry>
                <mesh filename="package://arctos_urdf_description/meshes/Link_2_1.stl" scale="0.001 0.001 0.001" />
            </geometry>
            <material name="paint_metallic_blue_2" />
        </visual>
        <collision>
            <origin rpy="0 0 0" xyz="0.05713 0.020356 -0.289378" />
            <geometry>
                <mesh filename="package://arctos_urdf_description/meshes/Link_2_1.stl" scale="0.001 0.001 0.001" />
            </geometry>
        </collision>
        <inertial>
            <origin rpy="0 0 0" xyz="0.055314283466519745 0.010843565259072822 0.11412354328486207" />
            <mass value="11.558090086674309" />
            <inertia ixx="0.128567" ixy="3e-06" ixz="0.001539" iyy="0.14463" iyz="-0.003293" izz="0.044463" />
        </inertial>
    </link>
    <link name="Link_3_1">
        <visual>
            <origin rpy="0 0 0" xyz="-0.043 0.019045 -0.550385" />
            <geometry>
                <mesh filename="package://arctos_urdf_description/meshes/Link_3_1.stl" scale="0.001 0.001 0.001" />
            </geometry>
            <material name="paint_metallic_blue_2" />
        </visual>
        <collision>
            <origin rpy="0 0 0" xyz="-0.043 0.019045 -0.550385" />
            <geometry>
                <mesh filename="package://arctos_urdf_description/meshes/Link_3_1.stl" scale="0.001 0.001 0.001" />
            </geometry>
        </collision>
        <inertial>
            <origin rpy="0 0 0" xyz="-0.04178369242643258 -0.03913025368943244 0.01221763827191602" />
            <mass value="3.601405589552794" />
            <inertia ixx="0.012497" ixy="-3.6e-05" ixz="-8.1e-05" iyy="0.006916" iyz="0.001536" izz="0.011789" />
        </inertial>
    </link>
    <link name="Link_4_1">
        <visual>
            <origin rpy="0 0 0" xyz="-1e-06 0.15874 -0.57209" />
            <geometry>
                <mesh filename="package://arctos_urdf_description/meshes/Link_4_1.stl" scale="0.001 0.001 0.001" />
            </geometry>
            <material name="paint_metallic_blue_2" />
        </visual>
        <collision>
            <origin rpy="0 0 0" xyz="-1e-06 0.15874 -0.57209" />
            <geometry>
                <mesh filename="package://arctos_urdf_description/meshes/Link_4_1.stl" scale="0.001 0.001 0.001" />
            </geometry>
        </collision>
        <inertial>
            <origin rpy="0 0 0" xyz="0.00021104999825562586 -0.06028834880207104 -0.0005408226217131773" />
            <mass value="3.7852887653107565" />
            <inertia ixx="0.011624" ixy="-9e-06" ixz="4e-06" iyy="0.011491" iyz="-7.1e-05" izz="0.017363" />
        </inertial>
    </link>
    <link name="Link_5_1">
        <visual>
            <origin rpy="0 0 0" xyz="0.039011 0.279927 -0.570316" />
            <geometry>
                <mesh filename="package://arctos_urdf_description/meshes/Link_5_1.stl" scale="0.001 0.001 0.001" />
            </geometry>
            <material name="paint_metallic_blue_2" />
        </visual>
        <collision>
            <origin rpy="0 0 0" xyz="0.039011 0.279927 -0.570316" />
            <geometry>
                <mesh filename="package://arctos_urdf_description/meshes/Link_5_1.stl" scale="0.001 0.001 0.001" />
            </geometry>
        </collision>
        <inertial>
            <origin rpy="0 0 0" xyz="0.0397291414278933 -0.012662394123331089 0.0007929187272999183" />
            <mass value="0.8319811655030993" />
            <inertia ixx="0.000732" ixy="-1.2e-05" ixz="5e-06" iyy="0.000958" iyz="-5e-06" izz="0.000907" />
        </inertial>
    </link>
    <link name="Link_6_1">
        <visual>
            <origin rpy="0 0 0" xyz="-0.000193 0.313762 -0.570316" />
            <geometry>
                <mesh filename="package://arctos_urdf_description/meshes/Link_6_1.stl" scale="0.001 0.001 0.001" />
            </geometry>
            <material name="paint_metallic_blue_2" />
        </visual>
        <collision>
            <origin rpy="0 0 0" xyz="-0.000193 0.313762 -0.570316" />
            <geometry>
                <mesh filename="package://arctos_urdf_description/meshes/Link_6_1.stl" scale="0.001 0.001 0.001" />
            </geometry>
        </collision>
        <inertial>
            <origin rpy="0 0 0" xyz="6.567946382108388e-08 -0.003042398377876454 -3.032508957279134e-07" />
            <mass value="0.10343478090890781" />
            <inertia ixx="5.2e-05" ixy="-0.0" ixz="0.0" iyy="0.000103" iyz="0.0" izz="5.2e-05" />
        </inertial>
    </link>
    <link name="Gripper_1">
        <visual>
            <origin rpy="0 0 0" xyz="-0.000193 0.319847 -0.570316" />
            <geometry>
                <mesh filename="package://arctos_urdf_description/meshes/Gripper_1.stl" scale="0.001 0.001 0.001" />
            </geometry>
            <material name="paint_metallic_blue_2" />
        </visual>
        <collision>
            <origin rpy="0 0 0" xyz="-0.000193 0.319847 -0.570316" />
            <geometry>
                <mesh filename="package://arctos_urdf_description/meshes/Gripper_1.stl" scale="0.001 0.001 0.001" />
            </geometry>
        </collision>
        <inertial>
            <origin rpy="0 0 0" xyz="0.0036112727264542635 -0.014760653808445767 -0.00103677815369696" />
            <mass value="0.5810486809925093" />
            <inertia ixx="0.000385" ixy="1e-05" ixz="3e-06" iyy="0.000495" iyz="-2e-06" izz="0.000263" />
        </inertial>
    </link>
    <joint name="gripper" type="fixed">
        <parent link="Link_6_1" />
        <child link="Gripper_1" />
        <origin rpy="0 0 0" xyz="0.0 -0.006085 0.0" />
        <axis xyz="0 0 0" />
        <limit effort="0" lower="0" upper="0" velocity="0" />
    </joint>
    <link name="Left_jaw_1">
        <visual>
            <origin rpy="0 0 0" xyz="-0.007934 0.359845 -0.599867" />
            <geometry>
                <mesh filename="package://arctos_urdf_description/meshes/Left_jaw_1.stl" scale="0.001 0.001 0.001" />
            </geometry>
            <material name="paint_metallic_blue_2" />
        </visual>
        <collision>
            <origin rpy="0 0 0" xyz="-0.007934 0.359845 -0.599867" />
            <geometry>
                <mesh filename="package://arctos_urdf_description/meshes/Left_jaw_1.stl" scale="0.001 0.001 0.001" />
            </geometry>
        </collision>
        <inertial>
            <origin rpy="0 0 0" xyz="-0.011142702480351952 -0.009692440309284511 -0.009385792627785827" />
            <mass value="0.07369602565859415" />
            <inertia ixx="1.1e-05" ixy="2e-06" ixz="-0.0" iyy="6e-06" iyz="-0.0" izz="1.4e-05" />
        </inertial>
    </link>
    <!-- <joint name="jaw1" type="prismatic"> -->
    <joint name="jaw1" type="prismatic">
        <parent link="Gripper_1" />
        <child link="Left_jaw_1" />
        <axis xyz="-0.0 0.0 -1.0" />
        <limit effort="100" lower="0.0" upper="0.015" velocity="100" />
        <origin rpy="0 0 0" xyz="0.007741 -0.039998 0.029551" />
        <dynamics damping="1" friction="10" />
    </joint>
    <transmission name="left_jaw_tran">
        <type>transmission_interface/SimpleTransmission</type>
        <joint name="jaw1">
            <hardwareInterface>hardware_interface/PositionJointInterface</hardwareInterface>
        </joint>
        <actuator name="actr_left_jaw">
            <hardwareInterface>hardware_interface/PositionJointInterface</hardwareInterface>
            <mechanicalReduction>1</mechanicalReduction>
        </actuator>
    </transmission>
    <link name="Right_jaw_1">
        <visual>
            <origin rpy="0 0 0" xyz="-0.007934 0.359845 -0.539867" />
            <geometry>
                <mesh filename="package://arctos_urdf_description/meshes/Right_jaw_1.stl" scale="0.001 0.001 0.001" />
            </geometry>
            <material name="paint_metallic_blue_2" />
        </visual>
        <collision>
            <origin rpy="0 0 0" xyz="-0.007934 0.359845 -0.539867" />
            <geometry>
                <mesh filename="package://arctos_urdf_description/meshes/Right_jaw_1.stl" scale="0.001 0.001 0.001" />
            </geometry>
        </collision>
        <inertial>
            <origin rpy="0 0 0" xyz="-0.008289104952972526 -0.009768535307719373 0.009395511902715814" />
            <mass value="0.07312902168719511" />
            <inertia ixx="1.1e-05" ixy="-1e-06" ixz="-1e-06" iyy="6e-06" iyz="0.0" izz="1.4e-05" />
        </inertial>
    </link>
    <!-- <joint name="jaw2" type="prismatic"> -->
    <joint name="jaw2" type="prismatic">
        <parent link="Gripper_1" />
        <child link="Right_jaw_1" />
        <axis xyz="0.0 -0.0 1.0" />
        <limit effort="100" lower="0.0" upper="0.015" velocity="100" />
        <origin rpy="0 0 0" xyz="0.007741 -0.039998 -0.030449" />
        <dynamics damping="1" friction="10" />
        <mimic joint="jaw1" multiplier="1.0" offset="0.0" />
    </joint>
    <transmission name="right_jaw_tran">
        <type>transmission_interface/SimpleTransmission</type>
        <joint name="jaw2">
            <hardwareInterface>hardware_interface/PositionJointInterface</hardwareInterface>
        </joint>
        <actuator name="actr_right_jaw">
            <hardwareInterface>hardware_interface/PositionJointInterface</hardwareInterface>
            <mechanicalReduction>1</mechanicalReduction>
        </actuator>
    </transmission>
    <gazebo>
        <plugin filename="libroboticsgroup_upatras_gazebo_mimic_joint_plugin.so" name="jaw2_mimic_joint_plugin">
            <joint>jaw1</joint>
            <mimicJoint>jaw2</mimicJoint>
            <multiplier>-1.0</multiplier>
            <offset>0</offset>
            <sensitiveness>0.0</sensitiveness>
            <maxEffort>200</maxEffort>
            <robotNamespace>/arctos</robotNamespace>
        </plugin>
        <plugin name="gazebo_ros_control" filename="libgazebo_ros_control.so">
            <robotNamespace>/</robotNamespace>
        </plugin>
    </gazebo>
    <gazebo>
        <plugin filename="libgazebo_grasp_fix.so" name="gazebo_grasp_fix">
            <arm>
                <arm_name>gripper</arm_name>
                <palm_link>Gripper_1</palm_link>
                <gripper_link>Right_jaw_1</gripper_link>
                <gripper_link>Left_jaw_1</gripper_link>
            </arm>
            <forces_angle_tolerance>100</forces_angle_tolerance>
            <update_rate>10</update_rate>
            <grip_count_threshold>4</grip_count_threshold>
            <max_grip_count>10</max_grip_count>
            <release_tolerance>0.005</release_tolerance>
            <disable_collision_on_attach>false</disable_collision_on_attach>
            <contact_topic>__default_topic__</contact_topic>
        </plugin>
    </gazebo>
    <joint name="joint1" type="continuous">
        <parent link="base_link" />
        <child link="Link_1_1" />
        <origin rpy="0 0 0" xyz="0.0 0.000529 0.111" />
        <axis xyz="-0.0 0.0 1.0" />
        <limit effort="100" lower="-3.141592653589793" upper="3.141592653589793" velocity="1" />
    </joint>
    <joint name="joint2" type="continuous">
        <parent link="Link_1_1" />
        <child link="Link_2_1" />
        <origin rpy="0 0 0" xyz="-0.05713 -0.020885 0.178378" />
        <axis xyz="1.0 -0.0 -0.0" />
        <limit effort="100" lower="-1.45" upper="2.3" velocity="1" />
    </joint>
    <joint name="joint3" type="continuous">
        <parent link="Link_2_1" />
        <child link="Link_3_1" />
        <origin rpy="0 0 0" xyz="0.10013 0.001311 0.261007" />
        <axis xyz="-1.0 -0.0 0.0" />
        <limit effort="100" lower="0.84" upper="1.85" velocity="1" />
    </joint>
    <joint name="joint4" type="continuous">
        <parent link="Link_3_1" />
        <child link="Link_4_1" />
        <origin rpy="0 0 0" xyz="-0.042999 -0.139695 0.021705" />
        <axis xyz="-0.0 1.0 -0.0" />
        <limit effort="100" lower="-3.141592653589793" upper="3.141592653589793" velocity="1" />
    </joint>
    <joint name="joint5" type="continuous">
        <parent link="Link_4_1" />
        <child link="Link_5_1" />
        <origin rpy="0 0 0" xyz="-0.039012 -0.121187 -0.001774" />
        <axis xyz="-1.0 -0.0 0.0" />
        <limit effort="100" lower="-1.55" upper="1.55" velocity="1" />
    </joint>
    <joint name="joint6" type="continuous">
        <parent link="Link_5_1" />
        <child link="Link_6_1" />
        <origin rpy="0 0 0" xyz="0.039204 -0.033835 0.0" />
        <axis xyz="-0.0 1.0 -0.0" />
        <limit effort="100" lower="-3.141592653589793" upper="3.141592653589793" velocity="1" />
    </joint>
    <transmission name="joint1_tran">
        <type>transmission_interface/SimpleTransmission</type>
        <joint name="joint1">
            <hardwareInterface>hardware_interface/PositionJointInterface</hardwareInterface>
        </joint>
        <actuator name="joint1_actr">
            <hardwareInterface>hardware_interface/PositionJointInterface</hardwareInterface>
            <mechanicalReduction>1</mechanicalReduction>
        </actuator>
    </transmission>
    <transmission name="joint2_tran">
        <type>transmission_interface/SimpleTransmission</type>
        <joint name="joint2">
            <hardwareInterface>hardware_interface/PositionJointInterface</hardwareInterface>
        </joint>
        <actuator name="joint2_actr">
            <hardwareInterface>hardware_interface/PositionJointInterface</hardwareInterface>
            <mechanicalReduction>1</mechanicalReduction>
        </actuator>
    </transmission>
    <transmission name="joint5_tran">
        <type>transmission_interface/SimpleTransmission</type>
        <joint name="joint5">
            <hardwareInterface>hardware_interface/PositionJointInterface</hardwareInterface>
        </joint>
        <actuator name="joint5_actr">
            <hardwareInterface>hardware_interface/PositionJointInterface</hardwareInterface>
            <mechanicalReduction>1</mechanicalReduction>
        </actuator>
    </transmission>
    <transmission name="joint3_tran">
        <type>transmission_interface/SimpleTransmission</type>
        <joint name="joint3">
            <hardwareInterface>hardware_interface/PositionJointInterface</hardwareInterface>
        </joint>
        <actuator name="joint3_actr">
            <hardwareInterface>hardware_interface/PositionJointInterface</hardwareInterface>
            <mechanicalReduction>1</mechanicalReduction>
        </actuator>
    </transmission>
    <transmission name="joint4_tran">
        <type>transmission_interface/SimpleTransmission</type>
        <joint name="joint4">
            <hardwareInterface>hardware_interface/PositionJointInterface</hardwareInterface>
        </joint>
        <actuator name="joint4_actr">
            <hardwareInterface>hardware_interface/PositionJointInterface</hardwareInterface>
            <mechanicalReduction>1</mechanicalReduction>
        </actuator>
    </transmission>
    <transmission name="joint6_tran">
        <type>transmission_interface/SimpleTransmission</type>
        <joint name="joint6">
            <hardwareInterface>hardware_interface/PositionJointInterface</hardwareInterface>
        </joint>
        <actuator name="joint6_actr">
            <hardwareInterface>hardware_interface/PositionJointInterface</hardwareInterface>
            <mechanicalReduction>1</mechanicalReduction>
        </actuator>
    </transmission>
    <!-- Gazebo plugin -->
    <gazebo>
        <plugin filename="libgazebo_ros_control.so" name="gazebo_ros_control">
            <robotNamespace>/arctos</robotNamespace>
        </plugin>
    </gazebo>
</robot>

